Workbook

Sheet produto
A1: Tipo de atividade | B1: Responsável | D1: Projeto | E1: account_id | F1: folder_id | G1: Situação da atividade | H1: Funcionalidade | I1: Sub-funcionalidade
A2: Análise de testes | B2: Adri | D2: [Widgets] | E2: 4874953 | F2: 6368994 | G2: Não iniciado | H2: Twygo | I2: Twygo
A3: Automação de testes | B3: Alexandre
A4: Bug produção | B4: Amauri | D4: Link documentação | E4: https://twygoead.sharepoint.com/:w:/s/Twygo-TeamHub-GPRODUTO/IQCEzNCeBOE5SaL4pPSCEk4zAXZmlGK5TisvlwGmmKVV2e0?e=K7kEuK Análise técnica: https://twygoead.sharepoint.com/:w:/r/sites/Twygo-TeamHub-GPRODUTO/_layouts/15/Doc.aspx?sourcedoc=%7B2C924C98-284F-4986-B343-E44A7EEDE34A%7D&file=%5BAn%C3%A1lise%20t%C3%A9cnica%5D%20Pain%C3%A9is%20dos%20usu%C3%A1rios%20(widgets)%20CRIADO%20EM%2002-01-2026.docx&action=default&mobileredirect=true&DefaultItemOpen=1
A5: Bug retrabalho | B5: Angelica | D5: Link Figma | E5: https://www.figma.com/make/mtD5lsjvipyXS2GxYGZEMi/Tela-de-meu-espa%C3%A7o-e-widgets-07-01-2026?fullscreen=1&t=ykc17x3aG6WcRjXj-1
A6: Deploy | B6: Eduardo
A7: Desenvolvimento | B7: Éverton
A8: Documentação | B8: Felipe
A9: Execução de testes | B9: Fred
A10: Indiretos - Cerimonias da Equipe | B10: Jeiel
A11: Reteste | B11: João
A12: Review | B12: Karla
A13: Spike | B13: Maluf
A14: Teste de mesa | B14: Milles
B15: Morona
B16: Vine Coelho
B17: Vini Lisboa

Sheet dev-qa
A1: Tipo da atividade | B1: Título da atividade | C1: Descrição | D1: Esforço estimado | E1: Início estimado | F1: Término estimado | G1: Responsável
A2: Spike | B2: Spike | C2: Descrição detalhada da atividade de Spike:
A3: Análise de testes | B3: Análise de testes | C3: - Mapa mental utilizando estrutura para conversão em .xml, com suítes, casos de testes - título, objetivo, pré-requisitos -, passos e resultado esperado) - Converter .xmind para .xml - Preparar estrutura (suítes de testes) e importar casos de testes para Testlink - Criar plano de testes/baselines - Adicionar e atribuir casos para execução | D3: 12
A4: Desenvolvimento | B4: Dev 1.1 - [Criação da nova lib] Adicionar lib react-grid-layout e criar componente principal do painel | C4: * Instalar biblioteca react-grid-layout. * Criar interfaces TypeScript essenciais. * Criar componente wrapper <GridContainer /> aceitando propriedades x, y, w, h. * Configurar breakpoints e colunas responsivas do grid. | D4: 8
A5: Desenvolvimento | B5: Dev 1.2 - [Criação da nova lib] Criar estrutura do front em componentes | C5: * Criar organização de pastas para os widgets. * Desenvolver container padrão (wrapper) com título, ícone e ações. * Implementar Factory que renderiza o widget correto baseado no WIDGET_TYPE. | D5: 8
A6: Desenvolvimento | B6: Dev 1.3 - [Criação da nova lib] Models e migrations | C6: Migrations: board_tabs: Criar tabela vinculada a events. board_widgets: Criar tabela vinculada a tabs, contendo layout_config (JSON). Feature Flag: Criar flags distintas: Gestão de Painéis Histórico: Garantir que todas as tabelas tenham organization_id para facilitar a exclusão do banco histórico. | D6: 2
A7: Teste de mesa | B7: Teste de mesa bloco 1 | C7: Teste de mesa - Atividades / Blocos: Bloco 1 | D7: 2
A8: Desenvolvimento | B8: Dev 2.1 - [Criação/listagem de painéis] Tela de criar/editar painel - Aba identificação | C8: #R5 * Criar rota new e edit. * Formulário React mapeando para os campos da tabela events (Nome, Descrição). * Coluna descrição deve ser um platejs. Para mostrar na tabela utilizar o helper: ""convertDescriptionToPlainText"" | D8: 6
A9: Desenvolvimento | B9: Dev 2.2 - [Criação/listagem de painéis] Criar a lista dos painéis (usuário + compartilhados) | C9: #R1, R2 * Renomear menu * Ajustar breadcrumb * Adicionar tab na tela de navegação, controlada pela Feature Flag de gestão. * Implementar tabela no frontend consumindo PanelsController#index. * Adicionar rota no routes.rb e PanelsController com action index. * Criar consultas utilizando padrão de use_case e criterias * Testes unitários * Sem coluna de ativar/desativar ainda na coluna "Ativo?" * Sem a pré-visualização de painéis ainda na visão de cards | D9: 8
A10: Desenvolvimento | B10: Dev 2.3 - [Criação/listagem de painéis] Adicionar coluna na listagem com a função de ativar/desativar | C10: RN 12 * Implementar toggle rápido na listagem (item 2.2) que atualiza o campo “Ativo” sem necessidade de entrar na tela de edição. * Implementar o modal de alerta, caso o painel esteja em uso por algum menu. | D10: 6
A11: Desenvolvimento | B11: Dev 2.4 - [Criação/listagem de painéis] Filtros e Pesquisa | C11: #R3 * Adicionar barra de busca por nome do painel. * Configurar filterControlProvider * Implementar filtros das colunas * Implementar filtros padrões | D11: 6
A12: Desenvolvimento | B12: Dev 2.5 - [Criação/listagem de painéis] Esconder painéis de listagens de events | C12: Aplicar escopos (default_scope ou filtros explícitos) para garantir que events kind='Panel' não apareçam em relatórios ou listagens de cursos/trilhas. | D12: 3
A13: Teste de mesa | B13: Teste de mesa bloco 2 | C13: Teste de mesa - Atividades / Blocos: Bloco 2 | D13: 2
A14: Execução de testes | B14: QA 2.1 - Listagem | C14: Descrição RN: #R1 RN1, 2, 3, 4 #R2 RN6, 7, 9, 10, 11, 13 Verificar sobre ordenação nas colunas Também validar: - Layout / cores / padrões - Traduções (conforme configuração do cadastro do usuário administrador - português / inglês / espanhol) - Responsividade desktop (1366x768 / 1920x1080 / 1536x864) / Zoom até 125% escala 100% / Zoom até 125% escala 125% - Usabilidade (navegação por TAB, escolhas por setas, confirmação com ENTER e sair/fechar com ESC - Paginação | D14: 2
... A52: Execução de testes | B52: QA 6.1 - Modo de uso > Painéis do usuário | C52: Descrição RN: #R11 R88, 89, 89.1, 89.2 Também validar: - Layout / cores / padrões - Traduções (conforme configuração do cadastro do usuário administrador - português / inglês / espanhol) - Responsividade desktop (1366x768 / 1920x1080 / 1536x864) - Usabilidade (navegação por TAB, escolhas por setas, confirmação com ENTER e sair/fechar com ESC | D52: 2
A53: Execução de testes | B53: QA 6.2 - Dashboard - Visão do aluno | D53: 2
A54: Execução de testes | B54: QA 6.3 - Mobile | C54: Validar: - Telas admin e aluno - DevTools (412x915 / 393x873 / 414x896) Horizontal e Vertical - Dispositivo real (navegador chrome) horizontal e vertical | D54: 6
A55: Desenvolvimento | B55: Dev 7.1 - [Workers] Criar worker para a migração dos painéis | C55: * Verificar se já existe painel padrão. Se não, criar um Event (Panel) com abas e widgets idênticos ao dashboard legado. * Atualizar o modo de uso da org, removendo o dashboard antigo e criando novo menu com mesmo nome e ícone do dashboard, só que usando o painel. | D55: 4
A56: Desenvolvimento | B56: Dev 7.2 - [Workers] Criar worker de reversão | C56: Script que reverte a configuração do modo de uso e restaura o acesso ao dashboard padrão anterior. | D56: 4
A57: Teste de mesa | B57: Teste de mesa bloco 7 | C57: Teste de mesa - Atividades / Blocos: Bloco 7 | D57: 2
A58: Execução de testes | B58: QA 7.1 - [Workers] Criar worker para a migração dos painéis | C58: * Verificar se já existe painel padrão. Se não, criar um Event (Panel) com abas e widgets idênticos ao dashboard legado. * Atualizar o modo de uso da org, removendo o dashboard antigo e criando novo menu com mesmo nome e ícone do dashboard, só que usando o painel. * Criar os shared events necessários. | D58: 2
A59: Execução de testes | B59: QA 7.2 - [Workers] Criar worker de reversão | C59: Script que reverte a configuração do modo de uso e restaura o acesso ao dashboard padrão anterior. | D59: 2
A60: Desenvolvimento | B60: Dev 8.1 - [Beta] Adicionar a tabela de preços e contrato | C60: Adicionar funcionalidade na tabela de preços e no contrato | D60: 4
A61: Desenvolvimento | B61: Dev 8.2 - [Beta] Aplicar bloqueios de contrato nas telas de edição e opções do modo de uso | C61: Aplicar tela padrão e modais de bloqueio de contrato | D61: 4
A62: Desenvolvimento | B62: Dev 8.3 - [Beta] Adicionar ao beta automático | D62: 2
A63: Desenvolvimento | B63: Dev 8.4 - [Beta] Adicionar painéis na org trial | C63: Será necessário incluírmos as informações do novo painel de dashboard do aluno na base da org trial, para que quando o trial for criado, puxar essas informações para dentro do modo de uso | D63: 4
A64: Teste de mesa | B64: Teste de mesa bloco 8 | C64: Teste de mesa - Atividades / Blocos: Bloco 8 | D64: 2
A65: Execução de testes | B65: QA 8.1 - Beta / Launch | C65: Plano de liberação com Beta automático | D65: 2
A66: Desenvolvimento | B66: Dev 9.1 - [Banco histórico] Adicionar tabelas à exclusão do banco histórico | C66: Incluir panel_tabs e panel_widgets nas rotinas de limpeza de dados baseadas em organization_id. | D66: 2
A67: Teste de mesa | B67: Teste de mesa bloco 9 | C67: Teste de mesa - Atividades / Blocos: Bloco 9 | D67: 2
A68: Execução de testes | B68: QA 9.1 - Banco histórico | C68: Descrição RN: #R13 RN91 Na atividade de DEV é obrigatório conter a relação de tabelas impactadas para testes por QA. Quando conhecimento das tabelas, atualizar esta descrição adicionando-as. | D68: 2
A69: Desenvolvimento | B69: Dev 10.1 - Salvar logs de widgets e panel_tabs | C69: Registrar logs estruturados nas ações de criação, edição e exclusão. Incluir IP do usuário e ID da Organização para auditoria. | D69: 6
A70: Teste de mesa | B70: Teste de mesa bloco 10 | C70: Teste de mesa - Atividades / Blocos: Bloco 10 | D70: 2
A71: Execução de testes | B71: QA 10.1 - Logs | C71: Descrição RN: #R14 RN92 Na atividade de DEV é obrigatório conter a relação de tabelas e bancos para testes por QA MySQL PostgreSQL Quando conhecimento das tabelas, atualizar esta descrição adicionando-as. | D71: 6
A72: Execução de testes | B72: QA 11.1 - Ambientes adicionais | C72: Impactos, restrições, observações - Ambientes adicionais | D72: 1
A73: Execução de testes | B73: QA 11.2 - Feature flag | C73: Feature flag desabilitada Feature flag habilitada + painéis criados e aplicados em modo de uso + desabilitar feature flag (verificar que "menu" com widgets é ocultado na visão do aluno) Verificar também caso o menu com widgets esteja marcado como 'Padrão' e a funcionalidade desabilitada via feature_flag | D73: 2
A74: Execução de testes | B74: QA 11.3 - Trial | C74: Conforme já alinhamos, estou mantendo esta atividade apenas para "repasse" em trial (devido à ocorrências dos últimos impactos não previstos) Repasse para criação de trial (via URL e API) URL: https://stage.twygoead.com/new/register/steps?1 API: https://stage.twygo.com/api/v2/external_onboarding Repasse nas exclusões de trial Todas as informações pré-definidas da SophiaTech Todas informações (pré-definidas e criadas pelos administradores) | D74: 2
... A78: Documentação | B78: Vídeo | C78: Obs.: 5 dias corridos antes da data de entrega (prazo para edição vídeo pelo time de Marketing) | D78: 6
A79: Reteste | B79: Buffer retrabalho | C79: Buffer retrabalho | D79: {=IF(Tabela1[[#This Row],[Título da atividade]]="", "", (SUM(SUMIFS(D:D, A:A, {"Execução de testes";"Desenvolvimento"})))*0.3)} -> 86.7
A80: Indiretos - Cerimonias da Equipe | B80: Review | C80: Review
...

Sheet .csv
A1: account_id (*) | B1: folder_id (*) | C1: situacao_atividade | D1: tipo (*) | E1: titulo (*) | F1: descricao | G1: esforco_estimado | H1: inicio_estimado | I1: termino_estimado | J1: funcionalidade | K1: sub_funcionalidade | L1: responsavel
A2: =IF(Tabela1[[#This Row],[Título da atividade]]="","",produto!$E$2) -> 4874953 | B2: =IF(Tabela1[[#This Row],[Título da atividade]]="","",produto!$F$2) -> 6368994 | C2: =IF(Tabela1[[#This Row],[Título da atividade]]="","",produto!$G$2) -> Não iniciado | D2: =IF(Tabela1[[#This Row],[Tipo da atividade]]="","",Tabela1[[#This Row],[Tipo da atividade]]) -> Spike | E2: =IF(Tabela1[[#This Row],[Título da atividade]]=""," ",_xlfn.CONCAT(produto!$D$2,"",Tabela1[[#This Row],[Título da atividade]])) -> [Widgets] Spike | F2: =IF(Tabela1[[#This Row],[Título da atividade]]="", "", IF(OR(Tabela1[[#This Row],[Tipo da atividade]]="Desenvolvimento", Tabela1[[#This Row],[Tipo da atividade]]="Execução de testes"), Tabela1[[#This Row],[Descrição]] & REPT(CHAR(10),2) & "Documentação: " & CHAR(10) & produto!$E$4 & REPT(CHAR(10),2) & "Protótipo: " & CHAR(10) & produto!$E$5, Tabela1[[#This Row],[Descrição]])) -> Descrição detalhada da atividade de Spike: | G2: =IF(Tabela1[[#This Row],[Título da atividade]]="","",IF(Tabela1[[#This Row],[Esforço estimado]]>0,Tabela1[[#This Row],[Esforço estimado]],"")) | H2: =IF(Tabela1[[#This Row],[Título da atividade]]="","",IF(Tabela1[[#This Row],[Início estimado]]>0,Tabela1[[#This Row],[Início estimado]],"")) | I2: =IF(Tabela1[[#This Row],[Título da atividade]]="","",IF(Tabela1[[#This Row],[Término estimado]]>0,Tabela1[[#This Row],[Término estimado]],"")) | J2: =IF(Tabela1[[#This Row],[Título da atividade]]="","",produto!$H$2) -> Twygo | K2: =IF(Tabela1[[#This Row],[Título da atividade]]="","",produto!$I$2) -> Twygo | L2: =IF(Tabela1[[#This Row],[Título da atividade]]="","",IF(Tabela1[[#This Row],[Responsável]]>0,Tabela1[[#This Row],[Responsável]],""))
A3: =IF(Tabela1[[#This Row],[Título da atividade]]="","",produto!$E$2) -> 4874953 | B3: =IF(Tabela1[[#This Row],[Título da atividade]]="","",produto!$F$2) -> 6368994 | C3: =IF(Tabela1[[#This Row],[Título da atividade]]="","",produto!$G$2) -> Não iniciado | D3: =IF(Tabela1[[#This Row],[Tipo da atividade]]="","",Tabela1[[#This Row],[Tipo da atividade]]) -> Análise de testes | E3: =IF(Tabela1[[#This Row],[Título da atividade]]=""," ",_xlfn.CONCAT(produto!$D$2,"",Tabela1[[#This Row],[Título da atividade]])) -> [Widgets] Análise de testes | F3: =IF(Tabela1[[#This Row],[Título da atividade]]="", "", IF(OR(Tabela1[[#This Row],[Tipo da atividade]]="Desenvolvimento", Tabela1[[#This Row],[Tipo da atividade]]="Execução de testes"), Tabela1[[#This Row],[Descrição]] & REPT(CHAR(10),2) & "Documentação: " & CHAR(10) & produto!$E$4 & REPT(CHAR(10),2) & "Protótipo: " & CHAR(10) & produto!$E$5, Tabela1[[#This Row],[Descrição]])) -> - Mapa mental utilizando estrutura para conversão em .xml, com suítes, casos de testes - título, objetivo, pré-requisitos -, passos e resultado esperado) - Converter .xmind para .xml - Preparar estrutura (suítes de testes) e importar casos de testes para Testlink - Criar plano de testes/baselines - Adicionar e atribuir casos para execução | G3: =IF(Tabela1[[#This Row],[Título da atividade]]="","",IF(Tabela1[[#This Row],[Esforço estimado]]>0,Tabela1[[#This Row],[Esforço estimado]],"")) -> 12 | H3: =IF(Tabela1[[#This Row],[Título da atividade]]="","",IF(Tabela1[[#This Row],[Início estimado]]>0,Tabela1[[#This Row],[Início estimado]],"")) | I3: =IF(Tabela1[[#This Row],[Título da atividade]]="","",IF(Tabela1[[#This Row],[Término estimado]]>0,Tabela1[[#This Row],[Término estimado]],"")) | J3: =IF(Tabela1[[#This Row],[Título da atividade]]="","",produto!$H$2) -> Twygo | K3: =IF(Tabela1[[#This Row],[Título da atividade]]="","",produto!$I$2) -> Twygo | L3: =IF(Tabela1[[#This Row],[Título da atividade]]="","",IF(Tabela1[[#This Row],[Responsável]]>0,Tabela1[[#This Row],[Responsável]],""))
A4: =IF(Tabela1[[#This Row],[Título da atividade]]="","",produto!$E$2) -> 4874953 | B4: =IF(Tabela1[[#This Row],[Título da atividade]]="","",produto!$F$2) -> 6368994 | C4: =IF(Tabela1[[#This Row],[Título da atividade]]="","",produto!$G$2) -> Não iniciado | D4: =IF(Tabela1[[#This Row],[Tipo da atividade]]="","",Tabela1[[#This Row],[Tipo da atividade]]) -> Desenvolvimento | E4: =IF(Tabela1[[#This Row],[Título da atividade]]=""," ",_xlfn.CONCAT(produto!$D$2,"",Tabela1[[#This Row],[Título da atividade]])) -> [Widgets] Dev 1.1 - [Criação da nova lib] Adicionar lib react-grid-layout e criar componente principal do painel | F4: =IF(Tabela1[[#This Row],[Título da atividade]]="", "", IF(OR(Tabela1[[#This Row],[Tipo da atividade]]="Desenvolvimento", Tabela1[[#This Row],[Tipo da atividade]]="Execução de testes"), Tabela1[[#This Row],[Descrição]] & REPT(CHAR(10),2) & "Documentação: " & CHAR(10) & produto!$E$4 & REPT(CHAR(10),2) & "Protótipo: " & CHAR(10) & produto!$E$5, Tabela1[[#This Row],[Descrição]])) -> * Instalar biblioteca react-grid-layout. * Criar interfaces TypeScript essenciais. * Criar componente wrapper <GridContainer /> aceitando propriedades x, y, w, h. * Configurar breakpoints e colunas responsivas do grid. Documentação: https://twygoead.sharepoint.com/:w:/s/Twygo-TeamHub-GPRODUTO/IQCEzNCeBOE5SaL4pPSCEk4zAXZmlGK5TisvlwGmmKVV2e0?e=K7kEuK Análise técnica: https://twygoead.sharepoint.com/:w:/r/sites/Twygo-TeamHub-GPRODUTO/_layouts/15/Doc.aspx?sourcedoc=%7B2C924C98-284F-4986-B343-E44A7EEDE34A%7D&file=%5BAn%C3%A1lise%20t%C3%A9cnica%5D%20Pain%C3%A9is%20dos%20usu%C3%A1rios%20(widgets)%20CRIADO%20EM%2002-01-2026.docx&action=default&mobileredirect=true&DefaultItemOpen=1 Protótipo: https://www.figma.com/make/mtD5lsjvipyXS2GxYGZEMi/Tela-de-meu-espa%C3%A7o-e-widgets-07-01-2026?fullscreen=1&t=ykc17x3aG6WcRjXj-1 | G4: =IF(Tabela1[[#This Row],[Título da atividade]]="","",IF(Tabela1[[#This Row],[Esforço estimado]]>0,Tabela1[[#This Row],[Esforço estimado]],"")) -> 8 | H4: =IF(Tabela1[[#This Row],[Título da atividade]]="","",IF(Tabela1[[#This Row],[Início estimado]]>0,Tabela1[[#This Row],[Início estimado]],"")) | I4: =IF(Tabela1[[#This Row],[Título da atividade]]="","",IF(Tabela1[[#This Row],[Término estimado]]>0,Tabela1[[#This Row],[Término estimado]],"")) | J4: =IF(Tabela1[[#This Row],[Título da atividade]]="","",produto!$H$2) -> Twygo | K4: =IF(Tabela1[[#This Row],[Título da atividade]]="","",produto!$I$2) -> Twygo | L4: =IF(Tabela1[[#This Row],[Título da atividade]]="","",IF(Tabela1[[#This Row],[Responsável]]>0,Tabela1[[#This Row],[Responsável]],""))
A5: =IF(Tabela1[[#This Row],[Título da atividade]]="","",produto!$E$2) -> 4874953 | B5: =IF(Tabela1[[#This Row],[Título da atividade]]="","",produto!$F$2) -> 6368994 | C5: =IF(Tabela1[[#This Row],[Título da atividade]]="","",produto!$G$2) -> Não iniciado | D5: =IF(Tabela1[[#This Row],[Tipo da atividade]]="","",Tabela1[[#This Row],[Tipo da atividade]]) -> Desenvolvimento | E5: =IF(Tabela1[[#This Row],[Título da atividade]]=""," ",_xlfn.CONCAT(produto!$D$2,"",Tabela1[[#This Row],[Título da atividade]])) -> [Widgets] Dev 1.2 - [Criação da nova lib] Criar estrutura do front em componentes | F5: =IF(Tabela1[[#This Row],[Título da atividade]]="", "", IF(OR(Tabela1[[#This Row],[Tipo da atividade]]="Desenvolvimento", Tabela1[[#This Row],[Tipo da atividade]]="Execução de testes"), Tabela1[[#This Row],[Descrição]] & REPT(CHAR(10),2) & "Documentação: " & CHAR(10) & produto!$E$4 & REPT(CHAR(10),2) & "Protótipo: " & CHAR(10) & produto!$E$5, Tabela1[[#This Row],[Descrição]])) -> * Criar organização de pastas para os widgets. * Desenvolver container padrão (wrapper) com título, ícone e ações. * Implementar Factory que renderiza o widget correto baseado no WIDGET_TYPE. Documentação: https://twygoead.sharepoint.com/:w:/s/Twygo-TeamHub-GPRODUTO/IQCEzNCeBOE5SaL4pPSCEk4zAXZmlGK5TisvlwGmmKVV2e0?e=K7kEuK Análise técnica: https://twygoead.sharepoint.com/:w:/r/sites/Twygo-TeamHub-GPRODUTO/_layouts/15/Doc.aspx?sourcedoc=%7B2C924C98-284F-4986-B343-E44A7EEDE34A%7D&file=%5BAn%C3%A1lise%20t%C3%A9cnica%5D%20Pain%C3%A9is%20dos%20usu%C3%A1rios%20(widgets)%20CRIADO%20EM%2002-01-2026.docx&action=default&mobileredirect=true&DefaultItemOpen=1 Protótipo: https://www.figma.com/make/mtD5lsjvipyXS2GxYGZEMi/Tela-de-meu-espa%C3%A7o-e-widgets-07-01-2026?fullscreen=1&t=ykc17x3aG6WcRjXj-1 | G5: =IF(Tabela1[[#This Row],[Título da atividade]]="","",IF(Tabela1[[#This Row],[Esforço estimado]]>0,Tabela1[[#This Row],[Esforço estimado]],"")) -> 8 | H5: =IF(Tabela1[[#This Row],[Título da atividade]]="","",IF(Tabela1[[#This Row],[Início estimado]]>0,Tabela1[[#This Row],[Início estimado]],"")) | I5: =IF(Tabela1[[#This Row],[Título da atividade]]="","",IF(Tabela1[[#This Row],[Término estimado]]>0,Tabela1[[#This Row],[Término estimado]],"")) | J5: =IF(Tabela1[[#This Row],[Título da atividade]]="","",produto!$H$2) -> Twygo | K5: =IF(Tabela1[[#This Row],[Título da atividade]]="","",produto!$I$2) -> Twygo | L5: =IF(Tabela1[[#This Row],[Título da atividade]]="","",IF(Tabela1[[#This Row],[Responsável]]>0,Tabela1[[#This Row],[Responsável]],""))
A6: =IF(Tabela1[[#This Row],[Título da atividade]]="","",produto!$E$2) -> 4874953 | B6: =IF(Tabela1[[#This Row],[Título da atividade]]="","",produto!$F$2) -> 6368994 | C6: =IF(Tabela1[[#This Row],[Título da atividade]]="","",produto!$G$2) -> Não iniciado | D6: =IF(Tabela1[[#This Row],[Tipo da atividade]]="","",Tabela1[[#This Row],[Tipo da atividade]]) -> Desenvolvimento | E6: =IF(Tabela1[[#This Row],[Título da atividade]]=""," ",_xlfn.CONCAT(produto!$D$2,"",Tabela1[[#This Row],[Título da atividade]])) -> [Widgets] Dev 1.3 - [Criação da nova lib] Models e migrations | F6: =IF(Tabela1[[#This Row],[Título da atividade]]="", "", IF(OR(Tabela1[[#This Row],[Tipo da atividade]]="Desenvolvimento", Tabela1[[#This Row],[Tipo da atividade]]="Execução de testes"), Tabela1[[#This Row],[Descrição]] & REPT(CHAR(10),2) & "Documentação: " & CHAR(10) & produto!$E$4 & REPT(CHAR(10),2) & "Protótipo: " & CHAR(10) & produto!$E$5, Tabela1[[#This Row],[Descrição]])) -> Migrations: board_tabs: Criar tabela vinculada a events. board_widgets: Criar tabela vinculada a tabs, contendo layout_config (JSON). Feature Flag: Criar flags distintas: Gestão de Painéis Histórico: Garantir que todas as tabelas tenham organization_id para facilitar a exclusão do banco histórico. Documentação: https://twygoead.sharepoint.com/:w:/s/Twygo-TeamHub-GPRODUTO/IQCEzNCeBOE5SaL4pPSCEk4zAXZmlGK5TisvlwGmmKVV2e0?e=K7kEuK Análise técnica: https://twygoead.sharepoint.com/:w:/r/sites/Twygo-TeamHub-GPRODUTO/_layouts/15/Doc.aspx?sourcedoc=%7B2C924C98-284F-4986-B343-E44A7EEDE34A%7D&file=%5BAn%C3%A1lise%20t%C3%A9cnica%5D%20Pain%C3%A9is%20dos%20usu%C3%A1rios%20(widgets)%20CRIADO%20EM%2002-01-2026.docx&action=default&mobileredirect=true&DefaultItemOpen=1 Protótipo: https://www.figma.com/make/mtD5lsjvipyXS2GxYGZEMi/Tela-de-meu-espa%C3%A7o-e-widgets-07-01-2026?fullscreen=1&t=ykc17x3aG6WcRjXj-1 | G6: =IF(Tabela1[[#This Row],[Título da atividade]]="","",IF(Tabela1[[#This Row],[Esforço estimado]]>0,Tabela1[[#This Row],[Esforço estimado]],"")) -> 2 | H6: =IF(Tabela1[[#This Row],[Título da atividade]]="","",IF(Tabela1[[#This Row],[Início estimado]]>0,Tabela1[[#This Row],[Início estimado]],"")) | I6: =IF(Tabela1[[#This Row],[Título da atividade]]="","",IF(Tabela1[[#This Row],[Término estimado]]>0,Tabela1[[#This Row],[Término estimado]],"")) | J6: =IF(Tabela1[[#This Row],[Título da atividade]]="","",produto!$H$2) -> Twygo | K6: =IF(Tabela1[[#This Row],[Título da atividade]]="","",produto!$I$2) -> Twygo | L6: =IF(Tabela1[[#This Row],[Título da atividade]]="","",IF(Tabela1[[#This Row],[Responsável]]>0,Tabela1[[#This Row],[Responsável]],""))
A7: =IF(Tabela1[[#This Row],[Título da atividade]]="","",produto!$E$2) -> 4874953 | B7: =IF(Tabela1[[#This Row],[Título da atividade]]="","",produto!$F$2) -> 6368994 | C7: =IF(Tabela1[[#This Row],[Título da atividade]]="","",produto!$G$2) -> Não iniciado | D7: =IF(Tabela1[[#This Row],[Tipo da atividade]]="","",Tabela1[[#This Row],[Tipo da atividade]]) -> Teste de mesa | E7: =IF(Tabela1[[#This Row],[Título da atividade]]=""," ",_xlfn.CONCAT(produto!$D$2,"",Tabela1[[#This Row],[Título da atividade]])) -> [Widgets] Teste de mesa bloco 1 | F7: =IF(Tabela1[[#This Row],[Título da atividade]]="", "", IF(OR(Tabela1[[#This Row],[Tipo da atividade]]="Desenvolvimento", Tabela1[[#This Row],[Tipo da atividade]]="Execução de testes"), Tabela1[[#This Row],[Descrição]] & REPT(CHAR(10),2) & "Documentação: " & CHAR(10) & produto!$E$4 & REPT(CHAR(10),2) & "Protótipo: " & CHAR(10) & produto!$E$5, Tabela1[[#This Row],[Descrição]])) -> Teste de mesa - Atividades / Blocos: Bloco 1 | G7: =IF(Tabela1[[#This Row],[Título da atividade]]="","",IF(Tabela1[[#This Row],[Esforço estimado]]>0,Tabela1[[#This Row],[Esforço estimado]],"")) -> 2 | H7: =IF(Tabela1[[#This Row],[Título da atividade]]="","",IF(Tabela1[[#This Row],[Início estimado]]>0,Tabela1[[#This Row],[Início estimado]],"")) | I7: =IF(Tabela1[[#This Row],[Título da atividade]]="","",IF(Tabela1[[#This Row],[Término estimado]]>0,Tabela1[[#This Row],[Término estimado]],"")) | J7: =IF(Tabela1[[#This Row],[Título da atividade]]="","",produto!$H$2) -> Twygo | K7: =IF(Tabela1[[#This Row],[Título da atividade]]="","",produto!$I$2) -> Twygo | L7: =IF(Tabela1[[#This Row],[Título da atividade]]="","",IF(Tabela1[[#This Row],[Responsável]]>0,Tabela1[[#This Row],[Responsável]],""))
A8: =IF(Tabela1[[#This Row],[Título da atividade]]="","",produto!$E$2) -> 4874953 | B8: =IF(Tabela1[[#This Row],[Título da atividade]]="","",produto!$F$2) -> 6368994 | C8: =IF(Tabela1[[#This Row],[Título da atividade]]="","",produto!$G$2) -> Não iniciado | D8: =IF(Tabela1[[#This Row],[Tipo da atividade]]="","",Tabela1[[#This Row],[Tipo da atividade]]) -> Desenvolvimento | E8: =IF(Tabela1[[#This Row],[Título da atividade]]=""," ",_xlfn.CONCAT(produto!$D$2,"",Tabela1[[#This Row],[Título da atividade]])) -> [Widgets] Dev 2.1 - [Criação/listagem de painéis] Tela de criar/editar painel - Aba identificação | F8: =IF(Tabela1[[#This Row],[Título da atividade]]="", "", IF(OR(Tabela1[[#This Row],[Tipo da atividade]]="Desenvolvimento", Tabela1[[#This Row],[Tipo da atividade]]="Execução de testes"), Tabela1[[#This Row],[Descrição]] & REPT(CHAR(10),2) & "Documentação: " & CHAR(10) & produto!$E$4 & REPT(CHAR(10),2) & "Protótipo: " & CHAR(10) & produto!$E$5, Tabela1[[#This Row],[Descrição]])) -> #R5 * Criar rota new e edit. * Formulário React mapeando para os campos da tabela events (Nome, Descrição). * Coluna descrição deve ser um platejs. Para mostrar na tabela utilizar o helper: ""convertDescriptionToPlainText"" Documentação: https://twygoead.sharepoint.com/:w:/s/Twygo-TeamHub-GPRODUTO/IQCEzNCeBOE5SaL4pPSCEk4zAXZmlGK5TisvlwGmmKVV2e0?e=K7kEuK Análise técnica: https://twygoead.sharepoint.com/:w:/r/sites/Twygo-TeamHub-GPRODUTO/_layouts/15/Doc.aspx?sourcedoc=%7B2C924C98-284F-4986-B343-E44A7EEDE34A%7D&file=%5BAn%C3%A1lise%20t%C3%A9cnica%5D%20Pain%C3%A9is%20dos%20usu%C3%A1rios%20(widgets)%20CRIADO%20EM%2002-01-2026.docx&action=default&mobileredirect=true&DefaultItemOpen=1 Protótipo: https://www.figma.com/make/mtD5lsjvipyXS2GxYGZEMi/Tela-de-meu-espa%C3%A7o-e-widgets-07-01-2026?fullscreen=1&t=ykc17x3aG6WcRjXj-1 | G8: =IF(Tabela1[[#This Row],[Título da atividade]]="","",IF(Tabela1[[#This Row],[Esforço estimado]]>0,Tabela1[[#This Row],[Esforço estimado]],"")) -> 6 | H8: =IF(Tabela1[[#This Row],[Título da atividade]]="","",IF(Tabela1[[#This Row],[Início estimado]]>0,Tabela1[[#This Row],[Início estimado]],"")) | I8: =IF(Tabela1[[#This Row],[Título da atividade]]="","",IF(Tabela1[[#This Row],[Término estimado]]>0,Tabela1[[#This Row],[Término estimado]],"")) | J8: =IF(Tabela1[[#This Row],[Título da atividade]]="","",produto!$H$2) -> Twygo | K8: =IF(Tabela1[[#This Row],[Título da atividade]]="","",produto!$I$2) -> Twygo | L8: =IF(Tabela1[[#This Row],[Título da atividade]]="","",IF(Tabela1[[#This Row],[Responsável]]>0,Tabela1[[#This Row],[Responsável]],""))
A9: =IF(Tabela1[[#This Row],[Título da atividade]]="","",produto!$E$2) -> 4874953 | B9: =IF(Tabela1[[#This Row],[Título da atividade]]="","",produto!$F$2) -> 6368994 | C9: =IF(Tabela1[[#This Row],[Título da atividade]]="","",produto!$G$2) -> Não iniciado | D9: =IF(Tabela1[[#This Row],[Tipo da atividade]]="","",Tabela1[[#This Row],[Tipo da atividade]]) -> Desenvolvimento | E9: =IF(Tabela1[[#This Row],[Título da atividade]]=""," ",_xlfn.CONCAT(produto!$D$2,"",Tabela1[[#This Row],[Título da atividade]])) -> [Widgets] Dev 2.2 - [Criação/listagem de painéis] Criar a lista dos painéis (usuário + compartilhados) | F9: =IF(Tabela1[[#This Row],[Título da atividade]]="", "", IF(OR(Tabela1[[#This Row],[Tipo da atividade]]="Desenvolvimento", Tabela1[[#This Row],[Tipo da atividade]]="Execução de testes"), Tabela1[[#This Row],[Descrição]] & REPT(CHAR(10),2) & "Documentação: " & CHAR(10) & produto!$E$4 & REPT(CHAR(10),2) & "Protótipo: " & CHAR(10) & produto!$E$5, Tabela1[[#This Row],[Descrição]])) -> #R1, R2 * Renomear menu * Ajustar breadcrumb * Adicionar tab na tela de navegação, controlada pela Feature Flag de gestão. * Implementar tabela no frontend consumindo PanelsController#index. * Adicionar rota no routes.rb e PanelsController com action index. * Criar consultas utilizando padrão de use_case e criterias * Testes unitários * Sem coluna de ativar/desativar ainda na coluna "Ativo?" * Sem a pré-visualização de painéis ainda na visão de cards Documentação: https://twygoead.sharepoint.com/:w:/s/Twygo-TeamHub-GPRODUTO/IQCEzNCeBOE5SaL4pPSCEk4zAXZmlGK5TisvlwGmmKVV2e0?e=K7kEuK Análise técnica: https://twygoead.sharepoint.com/:w:/r/sites/Twygo-TeamHub-GPRODUTO/_layouts/15/Doc.aspx?sourcedoc=%7B2C924C98-284F-4986-B343-E44A7EEDE34A%7D&file=%5BAn%C3%A1lise%20t%C3%A9cnica%5D%20Pain%C3%A9is%20dos%20usu%C3%A1rios%20(widgets)%20CRIADO%20EM%2002-01-2026.docx&action=default&mobileredirect=true&DefaultItemOpen=1 Protótipo: https://www.figma.com/make/mtD5lsjvipyXS2GxYGZEMi/Tela-de-meu-espa%C3%A7o-e-widgets-07-01-2026?fullscreen=1&t=ykc17x3aG6WcRjXj-1 | G9: =IF(Tabela1[[#This Row],[Título da atividade]]="","",IF(Tabela1[[#This Row],[Esforço estimado]]>0,Tabela1[[#This Row],[Esforço estimado]],"")) -> 8 | H9: =IF(Tabela1[[#This Row],[Título da atividade]]="","",IF(Tabela1[[#This Row],[Início estimado]]>0,Tabela1[[#This Row],[Início estimado]],"")) | I9: =IF(Tabela1[[#This Row],[Título da atividade]]="","",IF(Tabela1[[#This Row],[Término estimado]]>0,Tabela1[[#This Row],[Término estimado]],"")) | J9: =IF(Tabela1[[#This Row],[Título da atividade]]="","",produto!$H$2) -> Twygo | K9: =IF(Tabela1[[#This Row],[Título da atividade]]="","",produto!$I$2) -> Twygo | L9: =IF(Tabela1[[#This Row],[Título da atividade]]="","",IF(Tabela1[[#This Row],[Responsável]]>0,Tabela1[[#This Row],[Responsável]],""))
A10: =IF(Tabela1[[#This Row],[Título da atividade]]="","",produto!$E$2) -> 4874953 | B10: =IF(Tabela1[[#This Row],[Título da atividade]]="","",produto!$F$2) -> 6368994 | C10: =IF(Tabela1[[#This Row],[Título da atividade]]="","",produto!$G$2) -> Não iniciado | D10: =IF(Tabela1[[#This Row],[Tipo da atividade]]="","",Tabela1[[#This Row],[Tipo da atividade]]) -> Desenvolvimento | E10: =IF(Tabela1[[#This Row],[Título da atividade]]=""," ",_xlfn.CONCAT(produto!$D$2,"",Tabela1[[#This Row],[Título da atividade]])) -> [Widgets] Dev 2.3 - [Criação/listagem de painéis] Adicionar coluna na listagem com a função de ativar/desativar | F10: =IF(Tabela1[[#This Row],[Título da atividade]]="", "", IF(OR(Tabela1[[#This Row],[Tipo da atividade]]="Desenvolvimento", Tabela1[[#This Row],[Tipo da atividade]]="Execução de testes"), Tabela1[[#This Row],[Descrição]] & REPT(CHAR(10),2) & "Documentação: " & CHAR(10) & produto!$E$4 & REPT(CHAR(10),2) & "Protótipo: " & CHAR(10) & produto!$E$5, Tabela1[[#This Row],[Descrição]])) -> RN 12 * Implementar toggle rápido na listagem (item 2.2) que atualiza o campo “Ativo” sem necessidade de entrar na tela de edição. * Implementar o modal de alerta, caso o painel esteja em uso por algum menu. Documentação: https://twygoead.sharepoint.com/:w:/s/Twygo-TeamHub-GPRODUTO/IQCEzNCeBOE5SaL4pPSCEk4zAXZmlGK5TisvlwGmmKVV2e0?e=K7kEuK Análise técnica: https://twygoead.sharepoint.com/:w:/r/sites/Twygo-TeamHub-GPRODUTO/_layouts/15/Doc.aspx?sourcedoc=%7B2C924C98-284F-4986-B343-E44A7EEDE34A%7D&file=%5BAn%C3%A1lise%20t%C3%A9cnica%5D%20Pain%C3%A9is%20dos%20usu%C3%A1rios%20(widgets)%20CRIADO%20EM%2002-01-2026.docx&action=default&mobileredirect=true&DefaultItemOpen=1 Protótipo: https://www.figma.com/make/mtD5lsjvipyXS2GxYGZEMi/Tela-de-meu-espa%C3%A7o-e-widgets-07-01-2026?fullscreen=1&t=ykc17x3aG6WcRjXj-1 | G10: =IF(Tabela1[[#This Row],[Título da atividade]]="","",IF(Tabela1[[#This Row],[Esforço estimado]]>0,Tabela1[[#This Row],[Esforço estimado]],"")) -> 6 | H10: =IF(Tabela1[[#This Row],[Título da atividade]]="","",IF(Tabela1[[#This Row],[Início estimado]]>0,Tabela1[[#This Row],[Início estimado]],"")) | I10: =IF(Tabela1[[#This Row],[Título da atividade]]="","",IF(Tabela1[[#This Row],[Término estimado]]>0,Tabela1[[#This Row],[Término estimado]],"")) | J10: =IF(Tabela1[[#This Row],[Título da atividade]]="","",produto!$H$2) -> Twygo | K10: =IF(Tabela1[[#This Row],[Título da atividade]]="","",produto!$I$2) -> Twygo | L10: =IF(Tabela1[[#This Row],[Título da atividade]]="","",IF(Tabela1[[#This Row],[Responsável]]>0,Tabela1[[#This Row],[Responsável]],""))
A11: =IF(Tabela1[[#This Row],[Título da atividade]]="","",produto!$E$2) -> 4874953 | B11: =IF(Tabela1[[#This Row],[Título da atividade]]="","",produto!$F$2) -> 6368994 | C11: =IF(Tabela1[[#This Row],[Título da atividade]]="","",produto!$G$2) -> Não iniciado | D11: =IF(Tabela1[[#This Row],[Tipo da atividade]]="","",Tabela1[[#This Row],[Tipo da atividade]]) -> Desenvolvimento | E11: =IF(Tabela1[[#This Row],[Título da atividade]]=""," ",_xlfn.CONCAT(produto!$D$2,"",Tabela1[[#This Row],[Título da atividade]])) -> [Widgets] Dev 2.4 - [Criação/listagem de painéis] Filtros e Pesquisa | F11: =IF(Tabela1[[#This Row],[Título da atividade]]="", "", IF(OR(Tabela1[[#This Row],[Tipo da atividade]]="Desenvolvimento", Tabela1[[#This Row],[Tipo da atividade]]="Execução de testes"), Tabela1[[#This Row],[Descrição]] & REPT(CHAR(10),2) & "Documentação: " & CHAR(10) & produto!$E$4 & REPT(CHAR(10),2) & "Protótipo: " & CHAR(10) & produto!$E$5, Tabela1[[#This Row],[Descrição]])) -> #R3 * Adicionar barra de busca por nome do painel. * Configurar filterControlProvider * Implementar filtros das colunas * Implementar filtros padrões Documentação: https://twygoead.sharepoint.com/:w:/s/Twygo-TeamHub-GPRODUTO/IQCEzNCeBOE5SaL4pPSCEk4zAXZmlGK5TisvlwGmmKVV2e0?e=K7kEuK Análise técnica: https://twygoead.sharepoint.com/:w:/r/sites/Twygo-TeamHub-GPRODUTO/_layouts/15/Doc.aspx?sourcedoc=%7B2C924C98-284F-4986-B343-E44A7EEDE34A%7D&file=%5BAn%C3%A1lise%20t%C3%A9cnica%5D%20Pain%C3%A9is%20dos%20usu%C3%A1rios%20(widgets)%20CRIADO%20EM%2002-01-2026.docx&action=default&mobileredirect=true&DefaultItemOpen=1 Protótipo: https://www.figma.com/make/mtD5lsjvipyXS2GxYGZEMi/Tela-de-meu-espa%C3%A7o-e-widgets-07-01-2026?fullscreen=1&t=ykc17x3aG6WcRjXj-1 | G11: =IF(Tabela1[[#This Row],[Título da atividade]]="","",IF(Tabela1[[#This Row],[Esforço estimado]]>0,Tabela1[[#This Row],[Esforço estimado]],"")) -> 6 | H11: =IF(Tabela1[[#This Row],[Título da atividade]]="","",IF(Tabela1[[#This Row],[Início estimado]]>0,Tabela1[[#This Row],[Início estimado]],"")) | I11: =IF(Tabela1[[#This Row],[Título da atividade]]="","",IF(Tabela1[[#This Row],[Término estimado]]>0,Tabela1[[#This Row],[Término estimado]],"")) | J11: =IF(Tabela1[[#This Row],[Título da atividade]]="","",produto!$H$2) -> Twygo | K11: =IF(Tabela1[[#This Row],[Título da atividade]]="","",produto!$I$2) -> Twygo | L11: =IF(Tabela1[[#This Row],[Título da atividade]]="","",IF(Tabela1[[#This Row],[Responsável]]>0,Tabela1[[#This Row],[Responsável]],""))
A12: =IF(Tabela1[[#This Row],[Título da atividade]]="","",produto!$E$2) -> 4874953 | B12: =IF(Tabela1[[#This Row],[Título da atividade]]="","",produto!$F$2) -> 6368994 | C12: =IF(Tabela1[[#This Row],[Título da atividade]]="","",produto!$G$2) -> Não iniciado | D12: =IF(Tabela1[[#This Row],[Tipo da atividade]]="","",Tabela1[[#This Row],[Tipo da atividade]]) -> Desenvolvimento | E12: =IF(Tabela1[[#This Row],[Título da atividade]]=""," ",_xlfn.CONCAT(produto!$D$2,"",Tabela1[[#This Row],[Título da atividade]])) -> [Widgets] Dev 2.5 - [Criação/listagem de painéis] Esconder painéis de listagens de events | F12: =IF(Tabela1[[#This Row],[Título da atividade]]="", "", IF(OR(Tabela1[[#This Row],[Tipo da atividade]]="Desenvolvimento", Tabela1[[#This Row],[Tipo da atividade]]="Execução de testes"), Tabela1[[#This Row],[Descrição]] & REPT(CHAR(10),2) & "Documentação: " & CHAR(10) & produto!$E$4 & REPT(CHAR(10),2) & "Protótipo: " & CHAR(10) & produto!$E$5, Tabela1[[#This Row],[Descrição]])) -> Aplicar escopos (default_scope ou filtros explícitos) para garantir que events kind='Panel' não apareçam em relatórios ou listagens de cursos/trilhas. Documentação: https://twygoead.sharepoint.com/:w:/s/Twygo-TeamHub-GPRODUTO/IQCEzNCeBOE5SaL4pPSCEk4zAXZmlGK5TisvlwGmmKVV2e0?e=K7kEuK Análise técnica: https://twygoead.sharepoint.com/:w:/r/sites/Twygo-TeamHub-GPRODUTO/_layouts/15/Doc.aspx?sourcedoc=%7B2C924C98-284F-4986-B343-E44A7EEDE34A%7D&file=%5BAn%C3%A1lise%20t%C3%A9cnica%5D%20Pain%C3%A9is%20dos%20usu%C3%A1rios%20(widgets)%20CRIADO%20EM%2002-01-2026.docx&action=default&mobileredirect=true&DefaultItemOpen=1 Protótipo: https://www.figma.com/make/mtD5lsjvipyXS2GxYGZEMi/Tela-de-meu-espa%C3%A7o-e-widgets-07-01-2026?fullscreen=1&t=ykc17x3aG6WcRjXj-1 | G12: =IF(Tabela1[[#This Row],[Título da atividade]]="","",IF(Tabela1[[#This Row],[Esforço estimado]]>0,Tabela1[[#This Row],[Esforço estimado]],"")) -> 3 | H12: =IF(Tabela1[[#This Row],[Título da atividade]]="","",IF(Tabela1[[#This Row],[Início estimado]]>0,Tabela1[[#This Row],[Início estimado]],"")) | I12: =IF(Tabela1[[#This Row],[Título da atividade]]="","",IF(Tabela1[[#This Row],[Término estimado]]>0,Tabela1[[#This Row],[Término estimado]],"")) | J12: =IF(Tabela1[[#This Row],[Título da atividade]]="","",produto!$H$2) -> Twygo | K12: =IF(Tabela1[[#This Row],[Título da atividade]]="","",produto!$I$2) -> Twygo | L12: =IF(Tabela1[[#This Row],[Título da atividade]]="","",IF(Tabela1[[#This Row],[Responsável]]>0,Tabela1[[#This Row],[Responsável]],""))
A13: =IF(Tabela1[[#This Row],[Título da atividade]]="","",produto!$E$2) -> 4874953 | B13: =IF(Tabela1[[#This Row],[Título da atividade]]="","",produto!$F$2) -> 6368994 | C13: =IF(Tabela1[[#This Row],[Título da atividade]]="","",produto!$G$2) -> Não iniciado | D13: =IF(Tabela1[[#This Row],[Tipo da atividade]]="","",Tabela1[[#This Row],[Tipo da atividade]]) -> Teste de mesa | E13: =IF(Tabela1[[#This Row],[Título da atividade]]=""," ",_xlfn.CONCAT(produto!$D$2,"",Tabela1[[#This Row],[Título da atividade]])) -> [Widgets] Teste de mesa bloco 2 | F13: =IF(Tabela1[[#This Row],[Título da atividade]]="", "", IF(OR(Tabela1[[#This Row],[Tipo da atividade]]="Desenvolvimento", Tabela1[[#This Row],[Tipo da atividade]]="Execução de testes"), Tabela1[[#This Row],[Descrição]] & REPT(CHAR(10),2) & "Documentação: " & CHAR(10) & produto!$E$4 & REPT(CHAR(10),2) & "Protótipo: " & CHAR(10) & produto!$E$5, Tabela1[[#This Row],[Descrição]])) -> Teste de mesa - Atividades / Blocos: Bloco 2 | G13: =IF(Tabela1[[#This Row],[Título da atividade]]="","",IF(Tabela1[[#This Row],[Esforço estimado]]>0,Tabela1[[#This Row],[Esforço estimado]],"")) -> 2 | H13: =IF(Tabela1[[#This Row],[Título da atividade]]="","",IF(Tabela1[[#This Row],[Início estimado]]>0,Tabela1[[#This Row],[Início estimado]],"")) | I13: =IF(Tabela1[[#This Row],[Título da atividade]]="","",IF(Tabela1[[#This Row],[Término estimado]]>0,Tabela1[[#This Row],[Término estimado]],"")) | J13: =IF(Tabela1[[#This Row],[Título da atividade]]="","",produto!$H$2) -> Twygo | K13: =IF(Tabela1[[#This Row],[Título da atividade]]="","",produto!$I$2) -> Twygo | L13: =IF(Tabela1[[#This Row],[Título da atividade]]="","",IF(Tabela1[[#This Row],[Responsável]]>0,Tabela1[[#This Row],[Responsável]],""))
... A31: =IF(Tabela1[[#This Row],[Título da atividade]]="","",produto!$E$2) -> 4874953 | B31: =IF(Tabela1[[#This Row],[Título da atividade]]="","",produto!$F$2) -> 6368994 | C31: =IF(Tabela1[[#This Row],[Título da atividade]]="","",produto!$G$2) -> Não iniciado | D31: =IF(Tabela1[[#This Row],[Tipo da atividade]]="","",Tabela1[[#This Row],[Tipo da atividade]]) -> Desenvolvimento | E31: =IF(Tabela1[[#This Row],[Título da atividade]]=""," ",_xlfn.CONCAT(produto!$D$2,"",Tabela1[[#This Row],[Título da atividade]])) -> [Widgets] Dev 3.18 - [Aba layout] Adicionar modal ao trocar de aba (deseja salvar alterações) | F31: =IF(Tabela1[[#This Row],[Título da atividade]]="", "", IF(OR(Tabela1[[#This Row],[Tipo da atividade]]="Desenvolvimento", Tabela1[[#This Row],[Tipo da atividade]]="Execução de testes"), Tabela1[[#This Row],[Descrição]] & REPT(CHAR(10),2) & "Documentação: " & CHAR(10) & produto!$E$4 & REPT(CHAR(10),2) & "Protótipo: " & CHAR(10) & produto!$E$5, Tabela1[[#This Row],[Descrição]])) -> Utilizar lógica já existente e utilizada na tela de pacotes, para exibir modal que verifica se o usuário tem alterações não salvas Documentação: https://twygoead.sharepoint.com/:w:/s/Twygo-TeamHub-GPRODUTO/IQCEzNCeBOE5SaL4pPSCEk4zAXZmlGK5TisvlwGmmKVV2e0?e=K7kEuK Análise técnica: https://twygoead.sharepoint.com/:w:/r/sites/Twygo-TeamHub-GPRODUTO/_layouts/15/Doc.aspx?sourcedoc=%7B2C924C98-284F-4986-B343-E44A7EEDE34A%7D&file=%5BAn%C3%A1lise%20t%C3%A9cnica%5D%20Pain%C3%A9is%20dos%20usu%C3%A1rios%20(widgets)%20CRIADO%20EM%2002-01-2026.docx&action=default&mobileredirect=true&DefaultItemOpen=1 Protótipo: https://www.figma.com/make/mtD5lsjvipyXS2GxYGZEMi/Tela-de-meu-espa%C3%A7o-e-widgets-07-01-2026?fullscreen=1&t=ykc17x3aG6WcRjXj-1 | G31: =IF(Tabela1[[#This Row],[Título da atividade]]="","",IF(Tabela1[[#This Row],[Esforço estimado]]>0,Tabela1[[#This Row],[Esforço estimado]],"")) -> 3 | H31: =IF(Tabela1[[#This Row],[Título da atividade]]="","",IF(Tabela1[[#This Row],[Início estimado]]>0,Tabela1[[#This Row],[Início estimado]],"")) | I31: =IF(Tabela1[[#This Row],[Título da atividade]]="","",IF(Tabela1[[#This Row],[Término estimado]]>0,Tabela1[[#This Row],[Término estimado]],"")) | J31: =IF(Tabela1[[#This Row],[Título da atividade]]="","",produto!$H$2) -> Twygo | K31: =IF(Tabela1[[#This Row],[Título da atividade]]="","",produto!$I$2) -> Twygo | L31: =IF(Tabela1[[#This Row],[Título da atividade]]="","",IF(Tabela1[[#This Row],[Responsável]]>0,Tabela1[[#This Row],[Responsável]],""))
